<?xml version="1.0" ?>
<!-- =================================================================================== -->
<!-- |    This document was autogenerated by xacro from urdf/bb8.urdf.xacro            | -->
<!-- |    EDITING THIS FILE BY HAND IS NOT RECOMMENDED                                 | -->
<!-- =================================================================================== -->
<robot name="ORBIT">
  <!-- Fottprint, bottom of the sphere, contact point with the terrain -->
  <link name="base_footprint">
    <collision>
      <geometry>
        <cylinder length="0.449" radius="0.165"/>
      </geometry>
    </collision>
  </link>
  <!-- Center of the sphere, revolution pivit point for the head -->
  <link name="base_link">
    <visual>
      <geometry>
        <sphere radius="0.165"/>
      </geometry>
      <material name="blue">
        <color rgba="0 0 1 1"/>
      </material>
      <!-- <geometry>
                <mesh filename="$(find bb8)/meshes/sphere.stl"/>
            </geometry> -->
    </visual>
  </link>
  <!-- Servo link, revolution for the head -->
  <link name="servo_link"/>
  <!-- Head base, point where the middle of the head "touches" the sphere -->
  <link name="head_link">
    <visual>
      <geometry>
        <sphere radius="0.0825"/>
      </geometry>
      <material name="red">
        <color rgba="1 0 0 1"/>
      </material>
      <!-- <geometry>
                <mesh filename="$(find bb8)/meshes/sphere.stl"/>
            </geometry> -->
    </visual>
  </link>
  <!-- IMU in the sphere -->
  <link name="sphere_imu"/>
  <!-- Lidar -->
  <link name="laser"/>
  <!-- IMU in the head -->
  <link name="head_imu"/>
  <!-- Revolution center point for the head -->
  <joint name="base_joint" type="fixed">
    <parent link="base_footprint"/>
    <child link="base_link"/>
    <origin rpy="0 0 0" xyz="0 0 0.165"/>
  </joint>
  <!-- Fixed mount sphere IMU -->
  <joint name="sphere_imu_joint" type="fixed">
    <parent link="base_footprint"/>
    <child link="sphere_imu"/>
    <origin rpy="0 0 0" xyz="0 0 0.165"/>
  </joint>
  <!-- Revolute joint of the sphere: allows pitching only -->
  <joint name="servo_joint" type="revolute">
    <parent link="base_link"/>
    <child link="servo_link"/>
    <!-- Offset joint pivot radius above base center -->
    <origin rpy="0 0 0" xyz="0 0 0"/>
    <!-- Axis along Y for forward/back tilt -->
    <axis xyz="0 1 0"/>
    <!-- Limit motion to ±45° -->
    <limit effort="1.0" lower="-0.7853981633974483" upper="0.7853981633974483" velocity="1.0"/>
  </joint>
  <!-- Head link: Lenght of the servo link -->
  <joint name="head_joint" type="fixed">
    <parent link="servo_link"/>
    <child link="head_link"/>
    <origin rpy="0 0 0" xyz="0 0 0.165"/>
  </joint>
  <!-- Fixed mount lidar_height above head for lidar -->
  <joint name="lidar_joint" type="fixed">
    <parent link="head_link"/>
    <child link="laser"/>
    <origin rpy="0 0 0" xyz="0 0 0.119"/>
  </joint>
  <!-- Fixed mount head_imu_height above head for imu -->
  <joint name="head_imu_joint" type="fixed">
    <parent link="head_link"/>
    <child link="head_imu"/>
    <origin rpy="0 0 0" xyz="0 0 0.089"/>
  </joint>
</robot>
