<?xml version="1.0" ?>
<!-- =================================================================================== -->
<!-- |    This document was autogenerated by xacro from src/bb8/urdf/bb8.urdf.xacro    | -->
<!-- |    EDITING THIS FILE BY HAND IS NOT RECOMMENDED                                 | -->
<!-- =================================================================================== -->
<robot name="spherical_bot">
  <!-- Base Sphere -->
  <link name="base_link">
    <visual>
      <geometry>
        <sphere radius="0.165"/>
      </geometry>
      <material name="blue">
        <color rgba="0 0 1 1"/>
      </material>
      <!-- <geometry>
                <mesh filename="$(find bb8)/meshes/sphere.stl"/>
            </geometry> -->
    </visual>
    <collision>
      <geometry>
        <cylinder length="0.48" radius="0.165"/>
      </geometry>
    </collision>
  </link>
  <!-- Head, mesh contains lidar -->
  <link name="head_link">
    <visual>
      <geometry>
        <sphere radius="0.0825"/>
      </geometry>
      <material name="red">
        <color rgba="1 0 0 1"/>
      </material>
      <!-- <geometry>
                <mesh filename="$(find bb8)/meshes/sphere.stl"/>
            </geometry> -->
    </visual>
  </link>
  <!-- Lidar -->
  <link name="laser"/>
  <!-- IMU -->
  <link name="imu_link"/>
  <!-- Revolute joint above the sphere: allows pitching only -->
  <joint name="head_joint" type="revolute">
    <parent link="base_link"/>
    <child link="head_link"/>
    <!-- Offset joint pivot radius above base center -->
    <origin rpy="0 0 0" xyz="0 0 0.165"/>
    <!-- Axis along Y for forward/back tilt -->
    <axis xyz="0 1 0"/>
    <!-- Limit motion to ±45° -->
    <limit effort="1.0" lower="-0.7853981633974483" upper="0.7853981633974483" velocity="1.0"/>
  </joint>
  <!-- Fixed mount lidar_height above head for lidar, mesh contained in head -->
  <joint name="lidar_joint" type="fixed">
    <parent link="head_link"/>
    <child link="laser"/>
    <origin rpy="0 0 0" xyz="0 0 0.15"/>
  </joint>
  <!-- Fixed mount imu_height above head for imu -->
  <joint name="imu_joint" type="fixed">
    <parent link="head_link"/>
    <child link="imu_link"/>
    <origin rpy="0 0 0" xyz="0 0 0.13"/>
  </joint>
</robot>
